Workbook

Sheet Current Year
A1: FY26 CURRENT YEAR BUDGET - PRIMARY SOURCE
A2: Revenue & Expense by account. Sub-accounts/categories sum up to parent. YTD pulls from Progress Tracker.
A4: Account # | B4: Account Name | C4: Account Category | D4: Budget by Account | E4: Budget by Category | F4: YTD Actual | G4: % of Budget
A5: REVENUE
A6: 4000 | B6: Community Contributions | D6: =E7+E10+E11+E12 -> 385000 | F6: ='Progress Tracker'!U6 -> 54740 | G6: =IF(D6=0,0,F6/D6) -> 0.14218182
C7: Board Contributions | E7: =SUM(E8:E9) -> 80000 | F7: ='Progress Tracker'!U7 -> 4120 | G7: =IF(E7=0,0,F7/E7) -> 0.0515
C8: Leadership Board Contributions | E8: 20000 | F8: ='Progress Tracker'!U8 -> 1120 | G8: =IF(E8=0,0,F8/E8) -> 0.056
C9: Executive Board Contributions | E9: 60000 | F9: ='Progress Tracker'!U9 -> 3000 | G9: =IF(E9=0,0,F9/E9) -> 0.05
C10: Founding Donor (NFF) Contributions | E10: 150000 | F10: ='Progress Tracker'!U10 -> 40000 | G10: =IF(E10=0,0,F10/E10) -> 0.26666667
C11: Major Donor Contributions | E11: 100000 | F11: ='Progress Tracker'!U11 -> 0 | G11: =IF(E11=0,0,F11/E11) -> 0
C12: All Other Community Contributions | E12: 55000 | F12: ='Progress Tracker'!U12 -> 10620 | G12: =IF(E12=0,0,F12/E12) -> 0.19309091
A13: 4010 | B13: Merchandise | D13: 2000 | F13: ='Progress Tracker'!U13 -> 0 | G13: =IF(D13=0,0,F13/D13) -> 0
A14: 4020 | B14: Annual Gathering | D14: 20000 | F14: ='Progress Tracker'!U14 -> 0 | G14: =IF(D14=0,0,F14/D14) -> 0
A15: 4021 | B15: Gathering Scholarships | D15: 0 | F15: ='Progress Tracker'!U15 -> 0 | G15: =IF(D15=0,0,F15/D15) -> 0
A16: 4025 | B16: Fundraising Events | D16: 100000 | F16: ='Progress Tracker'!U16 -> 12899.79 | G16: =IF(D16=0,0,F16/D16) -> 0.1289979
A17: 4026 | B17: Learning Events | D17: =SUM(E18:E19) -> 10000 | F17: =SUM(F18:F19) -> 3615 | G17: =IF(D17=0,0,F17/D17) -> 0.3615
A18: 4027 | C18: Online Learning Events | E18: 5000 | F18: ='Progress Tracker'!U18 -> 3615 | G18: =IF(E18=0,0,F18/E18) -> 0.723
A19: 4028 | C19: In Person Learning Event | E19: 5000 | F19: ='Progress Tracker'!U19 -> 0 | G19: =IF(E19=0,0,F19/E19) -> 0
A20: 4030 | B20: Reimbursables/Misc Uncategorized | D20: 0 | F20: ='Progress Tracker'!U20 -> 0 | G20: =IF(D20=0,0,F20/D20) -> 0
A21: TOTAL REVENUE | D21: =D6+D13+D14+D15+D16+D17+D20 -> 517000 | E21: NA | F21: =F6+F13+F14+F15+F16+F17+F20 -> 71254.79 | G21: =IF(D21=0,0,F21/D21) -> 0.13782358
A23: EXPENSES
A24: 5100 | B24: Member Care | C24: Development | D24: 300 | F24: ='Progress Tracker'!U24 -> 0 | G24: =IF(D24=0,0,F24/D24) -> 0
A25: 5110 | B25: Impact Partner Care | C25: Development | D25: 300 | F25: ='Progress Tracker'!U25 -> 0 | G25: =IF(D25=0,0,F25/D25) -> 0
A26: 5200 | B26: Fundraising & Marketing Expenses | C26: Development | D26: 10000 | F26: ='Progress Tracker'!U26 -> 0 | G26: =IF(D26=0,0,F26/D26) -> 0
A27: 5210 | B27: Fundraising Event | C27: Development | D27: 25000 | F27: ='Progress Tracker'!U27 -> 0 | G27: =IF(D27=0,0,F27/D27) -> 0
A28: 5300 | B28: Bank & Donation Fees | C28: Overhead | D28: 4500 | F28: ='Progress Tracker'!U28 -> 0 | G28: =IF(D28=0,0,F28/D28) -> 0
A29: 5310 | B29: Subscription Services | C29: Overhead | D29: 7000 | F29: ='Progress Tracker'!U29 -> 0 | G29: =IF(D29=0,0,F29/D29) -> 0
A30: 5321 | B30: Leadership Travel | C30: Overhead | D30: 3500 | F30: ='Progress Tracker'!U30 -> 0 | G30: =IF(D30=0,0,F30/D30) -> 0
A31: 5323 | B31: Leadership Meetings | C31: Programs | D31: 2500 | F31: ='Progress Tracker'!U31 -> 0 | G31: =IF(D31=0,0,F31/D31) -> 0
A32: 5330 | B32: Postage and Mailing Supplies | C32: Overhead | D32: 350 | F32: ='Progress Tracker'!U32 -> 0 | G32: =IF(D32=0,0,F32/D32) -> 0
A33: 5340 | B33: Non-Profit Liability Ins (Alliance) | C33: Overhead | D33: 3300 | F33: ='Progress Tracker'!U33 -> 0 | G33: =IF(D33=0,0,F33/D33) -> 0
A34: 5350 | B34: Supplies | C34: Overhead | D34: 200 | F34: ='Progress Tracker'!U34 -> 0 | G34: =IF(D34=0,0,F34/D34) -> 0
A35: 5400 | B35: In Person Annual Event | C35: Programs | D35: 18000 | F35: ='Progress Tracker'!U35 -> 0 | G35: =IF(D35=0,0,F35/D35) -> 0
... A42: 5500 | B42: Grants | C42: Grantmaking | D42: 50000 | F42: ='Progress Tracker'!U42 -> 0 | G42: =IF(D42=0,0,F42/D42) -> 0
A43: 5600 | B43: Staff Costs - Michele | D43: =SUM(E44:E46) -> 183967 | F43: ='Progress Tracker'!U43 -> 0
B44: Michele (Dev) | C44: Development | E44: 55190 | F44: ='Progress Tracker'!U44 -> 0
B45: Michele (Prog) | C45: Programs | E45: 55190 | F45: ='Progress Tracker'!U45 -> 0
B46: Michele (OH) | C46: Overhead | E46: 73587 | F46: ='Progress Tracker'!U46 -> 0
A47: 5601 | B47: Staff Costs - Lynnette | D47: =SUM(E48:E50) -> 58713 | F47: ='Progress Tracker'!U47 -> 0
B48: Lynnette (Dev) | C48: Development | E48: 5871 | F48: ='Progress Tracker'!U48 -> 0
...

Sheet Revenue Detail
A1: REVENUE TRACKING BY SOURCE
A3: Revenue Source | B3: FY21 Actual | C3: FY22 Actual | D3: FY23 Actual | E3: FY24 Actual | F3: FY25 Actual | G3: FY26 Budget | H3: FY26 YTD | I3: FY26 % Plan
A4: Community Contributions | B4: 274317 | C4: 287970 | D4: 320435 | E4: 359823 | F4: 362109 | G4: ='Current Year'!D6 -> 385000 | H4: ='Progress Tracker'!U6 -> 54740 | I4: =IF(G4=0,0,H4/G4) -> 0.14218182
A5: Board Contributions | B5: 0 | C5: 0 | D5: 0 | E5: 13000 | F5: 0 | G5: ='Current Year'!E7 -> 80000 | H5: ='Progress Tracker'!U7 -> 4120 | I5: =IF(G5=0,0,H5/G5) -> 0.0515
A6: Leadership Board Contributions | B6: 0 | C6: 0 | D6: 0 | E6: 0 | F6: 0 | G6: ='Current Year'!E8 -> 20000 | H6: ='Progress Tracker'!U8 -> 1120 | I6: =IF(G6=0,0,H6/G6) -> 0.056
A7: Executive Board Contributions | B7: 0 | C7: 0 | D7: 0 | E7: 0 | F7: 0 | G7: ='Current Year'!E9 -> 60000 | H7: ='Progress Tracker'!U9 -> 3000 | I7: =IF(G7=0,0,H7/G7) -> 0.05
A8: Founding Donor (NFF) Contributions | B8: 200000 | C8: 205000 | D8: 200000 | E8: 250000 | F8: 175000 | G8: ='Current Year'!E10 -> 150000 | H8: ='Progress Tracker'!U10 -> 40000 | I8: =IF(G8=0,0,H8/G8) -> 0.26666667
A9: Major Donor Contributions | B9: 0 | C9: 0 | D9: 0 | E9: 0 | F9: 30000 | G9: ='Current Year'!E11 -> 100000 | H9: ='Progress Tracker'!U11 -> 0 | I9: =IF(G9=0,0,H9/G9) -> 0
A10: All Other Community Contributions | B10: 74317 | C10: 82970 | D10: 120435 | E10: 96823 | F10: 157109 | G10: ='Current Year'!E12 -> 55000 | H10: ='Progress Tracker'!U12 -> 10620 | I10: =IF(G10=0,0,H10/G10) -> 0.19309091
A11: Merchandise | B11: 963 | C11: 1443 | D11: 0 | E11: 0 | F11: 1100 | G11: ='Current Year'!D13 -> 2000 | H11: ='Progress Tracker'!U13 -> 0 | I11: =IF(G11=0,0,H11/G11) -> 0
A12: Annual Gathering | B12: 0 | C12: 0 | D12: 0 | E12: 0 | F12: 9323 | G12: ='Current Year'!D14 -> 20000 | H12: ='Progress Tracker'!U14 -> 0 | I12: =IF(G12=0,0,H12/G12) -> 0
A13: Gathering Scholarships | B13: 0 | C13: 0 | D13: 0 | E13: 0 | F13: 0 | G13: ='Current Year'!D15 -> 0 | H13: ='Progress Tracker'!U15 -> 0 | I13: =IF(G13=0,0,H13/G13) -> 0
A14: Fundraising Events | B14: 0 | C14: 0 | D14: 0 | E14: 0 | F14: 94011 | G14: ='Current Year'!D16 -> 100000 | H14: ='Progress Tracker'!U16 -> 12899.79 | I14: =IF(G14=0,0,H14/G14) -> 0.1289979
A15: Learning Events | B15: 0 | C15: 0 | D15: 0 | E15: 0 | F15: 6513 | G15: ='Current Year'!D17 -> 10000 | H15: ='Progress Tracker'!U17 -> 3615 | I15: =IF(G15=0,0,H15/G15) -> 0.3615
A16: Online Learning Events | B16: 0 | C16: 0 | D16: 0 | E16: 0 | F16: 0 | G16: ='Current Year'!E18 -> 5000 | H16: ='Progress Tracker'!U18 -> 3615 | I16: =IF(G16=0,0,H16/G16) -> 0.723
A17: In Person Learning Events | B17: 0 | C17: 0 | D17: 0 | E17: 0 | F17: 6513 | G17: ='Current Year'!E19 -> 5000 | H17: ='Progress Tracker'!U19 -> 0 | I17: =IF(G17=0,0,H17/G17) -> 0
A18: Reimbursables/Misc | B18: 0 | C18: 0 | D18: 0 | E18: 0 | F18: 1278 | G18: ='Current Year'!D20 -> 0 | H18: ='Progress Tracker'!U20 -> 0 | I18: =IF(G18=0,0,H18/G18) -> 0
A20: TOTAL REVENUE | B20: 275280 | C20: 289413 | D20: 320435 | E20: 359823 | F20: 474334 | G20: ='Current Year'!D21 -> 517000 | H20: ='Progress Tracker'!U21 -> 71254.79 | I20: =IF(G20=0,0,H20/G20) -> 0.13782358

Sheet Expense Detail
A1: FY26 EXPENSE DETAIL - MIRRORS CURRENT YEAR
A3: Account | B3: FY21 | C3: FY22 | D3: FY23 | E3: FY24 | F3: FY25 Actual | G3: FY26 Budget | H3: FY26 YTD | I3: FY26 % Plan
A4: EXPENSES
A5: Member Care | B5: 0 | C5: 0 | D5: 0 | E5: 0 | F5: 275 | G5: ='Current Year'!D24 -> 300 | H5: ='Progress Tracker'!U24 -> 0 | I5: =IF(G5=0,0,H5/G5) -> 0
A6: Impact Partner Care | B6: 0 | C6: 0 | D6: 0 | E6: 0 | F6: 218 | G6: ='Current Year'!D25 -> 300 | H6: ='Progress Tracker'!U25 -> 0 | I6: =IF(G6=0,0,H6/G6) -> 0
A7: Fundraising & Marketing Expenses | B7: 0 | C7: 0 | D7: 0 | E7: 0 | F7: 3011 | G7: ='Current Year'!D26 -> 10000 | H7: ='Progress Tracker'!U26 -> 0 | I7: =IF(G7=0,0,H7/G7) -> 0
A8: Fundraising Event | B8: 0 | C8: 0 | D8: 0 | E8: 0 | F8: 27273 | G8: ='Current Year'!D27 -> 25000 | H8: ='Progress Tracker'!U27 -> 0 | I8: =IF(G8=0,0,H8/G8) -> 0
A9: Bank & Donation Fees | B9: 0 | C9: 0 | D9: 0 | E9: 0 | F9: 4345 | G9: ='Current Year'!D28 -> 4500 | H9: ='Progress Tracker'!U28 -> 0 | I9: =IF(G9=0,0,H9/G9) -> 0
A10: Subscription Services | B10: 0 | C10: 0 | D10: 0 | E10: 0 | F10: 6808 | G10: ='Current Year'!D29 -> 7000 | H10: ='Progress Tracker'!U29 -> 0 | I10: =IF(G10=0,0,H10/G10) -> 0
A11: Leadership Travel | B11: 0 | C11: 0 | D11: 0 | E11: 0 | F11: 2181 | G11: ='Current Year'!D30 -> 3500 | H11: ='Progress Tracker'!U30 -> 0 | I11: =IF(G11=0,0,H11/G11) -> 0
A12: Leadership Meetings | B12: 0 | C12: 0 | D12: 0 | E12: 0 | F12: 1309 | G12: ='Current Year'!D31 -> 2500 | H12: ='Progress Tracker'!U31 -> 0 | I12: =IF(G12=0,0,H12/G12) -> 0
A13: Postage and Mailing Supplies | B13: 0 | C13: 0 | D13: 0 | E13: 0 | F13: 350 | G13: ='Current Year'!D32 -> 350 | H13: ='Progress Tracker'!U32 -> 0 | I13: =IF(G13=0,0,H13/G13) -> 0
A14: Non-Profit Liability Ins (Alliance) | B14: 0 | C14: 0 | D14: 0 | E14: 0 | F14: 3220 | G14: ='Current Year'!D33 -> 3300 | H14: ='Progress Tracker'!U33 -> 0 | I14: =IF(G14=0,0,H14/G14) -> 0
A15: Supplies | B15: 0 | C15: 0 | D15: 0 | E15: 0 | F15: 200 | G15: ='Current Year'!D34 -> 200 | H15: ='Progress Tracker'!U34 -> 0 | I15: =IF(G15=0,0,H15/G15) -> 0
A16: In Person Annual Event | B16: 0 | C16: 0 | D16: 0 | E16: 0 | F16: 22672 | G16: ='Current Year'!D35 -> 18000 | H16: ='Progress Tracker'!U35 -> 0 | I16: =IF(G16=0,0,H16/G16) -> 0
... A23: Grants | B23: 79973 | C23: 55570 | D23: 57000 | E23: 79800 | F23: 31603 | G23: ='Current Year'!D42 -> 50000 | H23: ='Progress Tracker'!U42 -> 0 | I23: =IF(G23=0,0,H23/G23) -> 0
A24: Staff Costs - Michele | G24: ='Current Year'!D43 -> 183967 | H24: ='Progress Tracker'!U43 -> 0 | I24: =IF(G24=0,0,H24/G24) -> 0
A25: Michele (Dev) | G25: ='Current Year'!E44 -> 55190 | H25: ='Progress Tracker'!U44 -> 0 | I25: =IF(G25=0,0,H25/G25) -> 0
A26: Michele (Prog) | G26: ='Current Year'!E45 -> 55190 | H26: ='Progress Tracker'!U45 -> 0 | I26: =IF(G26=0,0,H26/G26) -> 0
A27: Michele (OH) | G27: ='Current Year'!E46 -> 73587 | H27: ='Progress Tracker'!U46 -> 0 | I27: =IF(G27=0,0,H27/G27) -> 0
A28: Staff Costs - Lynnette | G28: ='Current Year'!D47 -> 58713 | H28: ='Progress Tracker'!U47 -> 0 | I28: =IF(G28=0,0,H28/G28) -> 0
A29: Lynnette (Dev) | G29: ='Current Year'!E48 -> 5871 | H29: ='Progress Tracker'!U48 -> 0 | I29: =IF(G29=0,0,H29/G29) -> 0
A30: Lynnette (Prog) | G30: ='Current Year'!E49 -> 44035 | H30: ='Progress Tracker'!U49 -> 0 | I30: =IF(G30=0,0,H30/G30) -> 0
A31: Lynnette (OH) | G31: ='Current Year'!E50 -> 8807 | H31: ='Progress Tracker'!U50 -> 0 | I31: =IF(G31=0,0,H31/G31) -> 0
A32: Kristin Malvadkar | G32: ='Current Year'!D51 -> 28000 | H32: ='Progress Tracker'!U51 -> 0 | I32: =IF(G32=0,0,H32/G32) -> 0
A33: Kristin (Prog) | G33: ='Current Year'!E52 -> 22400 | H33: ='Progress Tracker'!U52 -> 0 | I33: =IF(G33=0,0,H33/G33) -> 0
A34: Kristin (OH) | G34: ='Current Year'!E53 -> 5600 | H34: ='Progress Tracker'!U53 -> 0 | I34: =IF(G34=0,0,H34/G34) -> 0
A35: Lauren | G35: ='Current Year'!D54 -> 50000 | H35: ='Progress Tracker'!U54 -> 0 | I35: =IF(G35=0,0,H35/G35) -> 0
A36: Lauren (Dev) | G36: ='Current Year'!E55 -> 25000 | H36: ='Progress Tracker'!U55 -> 0 | I36: =IF(G36=0,0,H36/G36) -> 0
A37: Lauren (Prog) | G37: ='Current Year'!E56 -> 25000 | H37: ='Progress Tracker'!U56 -> 0 | I37: =IF(G37=0,0,H37/G37) -> 0
A38: Sharon Bennett (Admin) | G38: ='Current Year'!D57 -> 20000 | H38: ='Progress Tracker'!U57 -> 0 | I38: =IF(G38=0,0,H38/G38) -> 0
A39: Financial Services | G39: ='Current Year'!D58 -> 7500 | H39: ='Progress Tracker'!U58 -> 0 | I39: =IF(G39=0,0,H39/G39) -> 0
A40: Contractor Support (PM/DA) | G40: ='Current Year'!D59 -> 30000 | H40: ='Progress Tracker'!U59 -> 0 | I40: =IF(G40=0,0,H40/G40) -> 0
A42: TOTAL EXPENSES | B42: 233659 | C42: 283505 | D42: 339841 | E42: 370306 | F42: 437423 | G42: ='Current Year'!D61 -> 513280 | H42: ='Progress Tracker'!U60 -> 0 | I42: =IF(G42=0,0,H42/G42) -> 0
A44: EXPENSE CATEGORY SUBTOTALS
A45: Development: Donor & Partner Care | B45: 21341 | C45: 31773 | D45: 19862 | E45: 33964 | F45: 177910 | G45: ='Current Year'!E64 -> 121661
A46: Programs: Education, Allyship, Engagement | B46: 0 | C46: 0 | D46: 0 | E46: 114416 | F46: 173736 | G46: ='Current Year'!E65 -> 174475
A47: Overhead | B47: 132345 | C47: 196162 | D47: 262979 | E47: 142126 | F47: 54174 | G47: ='Current Year'!E66 -> 167144
A48: Grantmaking | B48: 79973 | C48: 55570 | D48: 57000 | E48: 79800 | F48: 31603 | G48: ='Current Year'!E67 -> 50000
A50: NET INCOME | B50: -32696 | C50: -78505 | D50: -139841 | E50: -10483 | F50: 36953 | G50: ='Current Year'!D69 -> 3720 | H50: ='Progress Tracker'!U62 -> 71254.79 | I50: =IF(G50=0,0,H50/G50) -> 19.154513

Sheet Progress Tracker
A1: FY26 PROGRESS TRACKER - Monthly Actuals by Account
A4: Acct # | B4: Account Name | C4: Category | D4: Budget | E4: Jan | F4: Feb | G4: Mar | H4: Q1 | I4: Apr | J4: May | K4: Jun | L4: Q2 | M4: Jul | N4: Aug | O4: Sep | P4: Q3 | Q4: Oct | R4: Nov | S4: Dec | T4: Q4 | U4: YTD | V4: % Bgt
A5: REVENUE
A6: 4000 | B6: Community Contributions | D6: 385000 | E6: =E7+E10+E11+E12 -> 2265 | F6: =F7+F10+F11+F12 -> 47815 | G6: =G7+G10+G11+G12 -> 4660 | H6: =H7+H10+H11+H12 -> 54740 | I6: =I7+I10+I11+I12 -> 0 | J6: =J7+J10+J11+J12 -> 0 | K6: =K7+K10+K11+K12 -> 0 | L6: =L7+L10+L11+L12 -> 0 | ... T6: =T7+T10+T11+T12 -> 0 | U6: =H6+L6+P6+T6 -> 54740 | V6: =IF(D6=0,0,U6/D6) -> 0.14218182
B7: Board Contributions | C7: Board Contributions | D7: 80000 | E7: =SUM(E8:E9) -> 460 | F7: =SUM(F8:F9) -> 3560 | G7: =SUM(G8:G9) -> 100 | H7: =SUM(H8:H9) -> 4120 | I7: =SUM(I8:I9) -> 0 | J7: =SUM(J8:J9) -> 0 | K7: =SUM(K8:K9) -> 0 | L7: =SUM(L8:L9) -> 0 | ... T7: =SUM(T8:T9) -> 0 | U7: =H7+L7+P7+T7 -> 4120 | V7: =IF(D7=0,0,U7/D7) -> 0.0515
B8: Leadership Board Contributions | C8: Leadership Board Contributions | D8: 20000 | E8: 460 | F8: 560 | G8: 100 | H8: =SUM(E8:G8) -> 1120 | L8: =SUM(I8:K8) -> 0 | P8: =SUM(M8:O8) -> 0 | T8: =SUM(Q8:S8) -> 0 | U8: =H8+L8+P8+T8 -> 1120 | V8: =IF(D8=0,0,U8/D8) -> 0.056
B9: Executive Board Contributions | C9: Executive Board Contributions | D9: 60000 | E9: 0 | F9: 3000 | G9: 0 | H9: =SUM(E9:G9) -> 3000 | L9: =SUM(I9:K9) -> 0 | P9: =SUM(M9:O9) -> 0 | T9: =SUM(Q9:S9) -> 0 | U9: =H9+L9+P9+T9 -> 3000 | V9: =IF(D9=0,0,U9/D9) -> 0.05
B10: Founding Donor (NFF) Contributions | C10: Founding Donor (NFF) Contributions | D10: 150000 | E10: 0 | F10: 40000 | G10: 0 | H10: =SUM(E10:G10) -> 40000 | L10: =SUM(I10:K10) -> 0 | P10: =SUM(M10:O10) -> 0 | T10: =SUM(Q10:S10) -> 0 | U10: =H10+L10+P10+T10 -> 40000 | V10: =IF(D10=0,0,U10/D10) -> 0.26666667
B11: Major Donor Contributions | C11: Major Donor Contributions | D11: 100000 | E11: 0 | F11: 0 | G11: 0 | H11: =SUM(E11:G11) -> 0 | L11: =SUM(I11:K11) -> 0 | P11: =SUM(M11:O11) -> 0 | T11: =SUM(Q11:S11) -> 0 | U11: =H11+L11+P11+T11 -> 0 | V11: =IF(D11=0,0,U11/D11) -> 0
B12: All Other Community Contributions | C12: All Other Community Contributions | D12: 55000 | E12: 1805 | F12: 4255 | G12: 4560 | H12: =SUM(E12:G12) -> 10620 | L12: =SUM(I12:K12) -> 0 | P12: =SUM(M12:O12) -> 0 | T12: =SUM(Q12:S12) -> 0 | U12: =H12+L12+P12+T12 -> 10620 | V12: =IF(D12=0,0,U12/D12) -> 0.19309091
A13: 4010 | B13: Merchandise | D13: 2000 | H13: =SUM(E13:G13) -> 0 | L13: =SUM(I13:K13) -> 0 | P13: =SUM(M13:O13) -> 0 | T13: =SUM(Q13:S13) -> 0 | U13: =H13+L13+P13+T13 -> 0 | V13: =IF(D13=0,0,U13/D13) -> 0
A14: 4020 | B14: Annual Gathering | D14: 20000 | H14: =SUM(E14:G14) -> 0 | L14: =SUM(I14:K14) -> 0 | P14: =SUM(M14:O14) -> 0 | T14: =SUM(Q14:S14) -> 0 | U14: =H14+L14+P14+T14 -> 0 | V14: =IF(D14=0,0,U14/D14) -> 0
A15: 4021 | B15: Gathering Scholarships | D15: 0 | H15: =SUM(E15:G15) -> 0 | L15: =SUM(I15:K15) -> 0 | P15: =SUM(M15:O15) -> 0 | T15: =SUM(Q15:S15) -> 0 | U15: =H15+L15+P15+T15 -> 0 | V15: =IF(D15=0,0,U15/D15) -> 0
A16: 4025 | B16: Fundraising Events | D16: 100000 | E16: 0 | F16: 6506.85 | G16: 6392.94 | H16: =SUM(E16:G16) -> 12899.79 | L16: =SUM(I16:K16) -> 0 | P16: =SUM(M16:O16) -> 0 | T16: =SUM(Q16:S16) -> 0 | U16: =H16+L16+P16+T16 -> 12899.79 | V16: =IF(D16=0,0,U16/D16) -> 0.1289979
A17: 4026 | B17: Learning Events | D17: 10000 | E17: =SUM(E18:E19) -> 2400 | F17: =SUM(F18:F19) -> 640 | G17: =SUM(G18:G19) -> 575 | H17: =SUM(H18:H19) -> 3615 | I17: =SUM(I18:I19) -> 0 | J17: =SUM(J18:J19) -> 0 | K17: =SUM(K18:K19) -> 0 | L17: =SUM(L18:L19) -> 0 | ... T17: =SUM(T18:T19) -> 0 | U17: =H17+L17+P17+T17 -> 3615 | V17: =IF(D17=0,0,U17/D17) -> 0.3615
A18: 4027 | B18: Online Learning Events | C18: Online Learning Events | D18: 5000 | E18: 2400 | F18: 640 | G18: 575 | H18: =SUM(E18:G18) -> 3615 | L18: =SUM(I18:K18) -> 0 | P18: =SUM(M18:O18) -> 0 | T18: =SUM(Q18:S18) -> 0 | U18: =H18+L18+P18+T18 -> 3615 | V18: =IF(D18=0,0,U18/D18) -> 0.723
A19: 4028 | B19: In Person Learning Events | C19: In Person Learning Event | D19: 5000 | H19: =SUM(E19:G19) -> 0 | L19: =SUM(I19:K19) -> 0 | P19: =SUM(M19:O19) -> 0 | T19: =SUM(Q19:S19) -> 0 | U19: =H19+L19+P19+T19 -> 0 | V19: =IF(D19=0,0,U19/D19) -> 0
A20: 4030 | B20: Reimbursables/Misc Uncategorized | D20: 0 | H20: =SUM(E20:G20) -> 0 | L20: =SUM(I20:K20) -> 0 | P20: =SUM(M20:O20) -> 0 | T20: =SUM(Q20:S20) -> 0 | U20: =H20+L20+P20+T20 -> 0 | V20: =IF(D20=0,0,U20/D20) -> 0
A21: TOTAL REVENUE | D21: 517000 | E21: =E6+E13+E14+E15+E16+E17+E20 -> 4665 | F21: =F6+F13+F14+F15+F16+F17+F20 -> 54961.85 | G21: =G6+G13+G14+G15+G16+G17+G20 -> 11627.94 | H21: =H6+H13+H14+H15+H16+H17+H20 -> 71254.79 | I21: =I6+I13+I14+I15+I16+I17+I20 -> 0 | J21: =J6+J13+J14+J15+J16+J17+J20 -> 0 | K21: =K6+K13+K14+K15+K16+K17+K20 -> 0 | L21: =L6+L13+L14+L15+L16+L17+L20 -> 0 | ... T21: =T6+T13+T14+T15+T16+T17+T20 -> 0 | U21: =H21+L21+P21+T21 -> 71254.79 | V21: =IF(D21=0,0,U21/D21) -> 0.13782358
A23: EXPENSES
A24: 5100 | B24: Member Care | C24: Development | D24: 300 | H24: =SUM(E24:G24) -> 0 | L24: =SUM(I24:K24) -> 0 | P24: =SUM(M24:O24) -> 0 | T24: =SUM(Q24:S24) -> 0 | U24: =H24+L24+P24+T24 -> 0 | V24: =IF(D24=0,0,U24/D24) -> 0
A25: 5110 | B25: Impact Partner Care | C25: Development | D25: 300 | H25: =SUM(E25:G25) -> 0 | L25: =SUM(I25:K25) -> 0 | P25: =SUM(M25:O25) -> 0 | T25: =SUM(Q25:S25) -> 0 | U25: =H25+L25+P25+T25 -> 0 | V25: =IF(D25=0,0,U25/D25) -> 0
A26: 5200 | B26: Fundraising & Marketing Expenses | C26: Development | D26: 10000 | H26: =SUM(E26:G26) -> 0 | L26: =SUM(I26:K26) -> 0 | P26: =SUM(M26:O26) -> 0 | T26: =SUM(Q26:S26) -> 0 | U26: =H26+L26+P26+T26 -> 0 | V26: =IF(D26=0,0,U26/D26) -> 0
A27: 5210 | B27: Fundraising Event | C27: Development | D27: 25000 | H27: =SUM(E27:G27) -> 0 | L27: =SUM(I27:K27) -> 0 | P27: =SUM(M27:O27) -> 0 | T27: =SUM(Q27:S27) -> 0 | U27: =H27+L27+P27+T27 -> 0 | V27: =IF(D27=0,0,U27/D27) -> 0
A28: 5300 | B28: Bank & Donation Fees | C28: Overhead | D28: 4500 | H28: =SUM(E28:G28) -> 0 | L28: =SUM(I28:K28) -> 0 | P28: =SUM(M28:O28) -> 0 | T28: =SUM(Q28:S28) -> 0 | U28: =H28+L28+P28+T28 -> 0 | V28: =IF(D28=0,0,U28/D28) -> 0
A29: 5310 | B29: Subscription Services | C29: Overhead | D29: 7000 | H29: =SUM(E29:G29) -> 0 | L29: =SUM(I29:K29) -> 0 | P29: =SUM(M29:O29) -> 0 | T29: =SUM(Q29:S29) -> 0 | U29: =H29+L29+P29+T29 -> 0 | V29: =IF(D29=0,0,U29/D29) -> 0
A30: 5321 | B30: Leadership Travel | C30: Overhead | D30: 3500 | H30: =SUM(E30:G30) -> 0 | L30: =SUM(I30:K30) -> 0 | P30: =SUM(M30:O30) -> 0 | T30: =SUM(Q30:S30) -> 0 | U30: =H30+L30+P30+T30 -> 0 | V30: =IF(D30=0,0,U30/D30) -> 0
A31: 5323 | B31: Leadership Meetings | C31: Programs | D31: 2500 | H31: =SUM(E31:G31) -> 0 | L31: =SUM(I31:K31) -> 0 | P31: =SUM(M31:O31) -> 0 | T31: =SUM(Q31:S31) -> 0 | U31: =H31+L31+P31+T31 -> 0 | V31: =IF(D31=0,0,U31/D31) -> 0
A32: 5330 | B32: Postage and Mailing Supplies | C32: Overhead | D32: 350 | H32: =SUM(E32:G32) -> 0 | L32: =SUM(I32:K32) -> 0 | P32: =SUM(M32:O32) -> 0 | T32: =SUM(Q32:S32) -> 0 | U32: =H32+L32+P32+T32 -> 0 | V32: =IF(D32=0,0,U32/D32) -> 0
A33: 5340 | B33: Non-Profit Liability Ins (Alliance) | C33: Overhead | D33: 3300 | H33: =SUM(E33:G33) -> 0 | L33: =SUM(I33:K33) -> 0 | P33: =SUM(M33:O33) -> 0 | T33: =SUM(Q33:S33) -> 0 | U33: =H33+L33+P33+T33 -> 0 | V33: =IF(D33=0,0,U33/D33) -> 0
A34: 5350 | B34: Supplies | C34: Overhead | D34: 200 | H34: =SUM(E34:G34) -> 0 | L34: =SUM(I34:K34) -> 0 | P34: =SUM(M34:O34) -> 0 | T34: =SUM(Q34:S34) -> 0 | U34: =H34+L34+P34+T34 -> 0 | V34: =IF(D34=0,0,U34/D34) -> 0
A35: 5400 | B35: In Person Annual Event | C35: Programs | D35: 18000 | H35: =SUM(E35:G35) -> 0 | L35: =SUM(I35:K35) -> 0 | P35: =SUM(M35:O35) -> 0 | T35: =SUM(Q35:S35) -> 0 | U35: =H35+L35+P35+T35 -> 0 | V35: =IF(D35=0,0,U35/D35) -> 0
... A42: 5500 | B42: Grants | C42: Grantmaking | D42: 50000 | H42: =SUM(E42:G42) -> 0 | L42: =SUM(I42:K42) -> 0 | P42: =SUM(M42:O42) -> 0 | T42: =SUM(Q42:S42) -> 0 | U42: =H42+L42+P42+T42 -> 0 | V42: =IF(D42=0,0,U42/D42) -> 0
A43: 5600 | B43: Staff Costs - Michele | D43: 183967 | H43: =SUM(E43:G43) -> 0 | L43: =SUM(I43:K43) -> 0 | P43: =SUM(M43:O43) -> 0 | T43: =SUM(Q43:S43) -> 0 | U43: =H43+L43+P43+T43 -> 0 | V43: =IF(D43=0,0,U43/D43) -> 0
B44: Michele (Dev) | C44: Development | D44: 55190 | H44: =SUM(E44:G44) -> 0 | L44: =SUM(I44:K44) -> 0 | P44: =SUM(M44:O44) -> 0 | T44: =SUM(Q44:S44) -> 0 | U44: =H44+L44+P44+T44 -> 0 | V44: =IF(D44=0,0,U44/D44) -> 0
B45: Michele (Prog) | C45: Programs | D45: 55190 | H45: =SUM(E45:G45) -> 0 | L45: =SUM(I45:K45) -> 0 | P45: =SUM(M45:O45) -> 0 | T45: =SUM(Q45:S45) -> 0 | U45: =H45+L45+P45+T45 -> 0 | V45: =IF(D45=0,0,U45/D45) -> 0
B46: Michele (OH) | C46: Overhead | D46: 73587 | H46: =SUM(E46:G46) -> 0 | L46: =SUM(I46:K46) -> 0 | P46: =SUM(M46:O46) -> 0 | T46: =SUM(Q46:S46) -> 0 | U46: =H46+L46+P46+T46 -> 0 | V46: =IF(D46=0,0,U46/D46) -> 0
A47: 5601 | B47: Staff Costs - Lynnette | D47: 58713 | H47: =SUM(E47:G47) -> 0 | L47: =SUM(I47:K47) -> 0 | P47: =SUM(M47:O47) -> 0 | T47: =SUM(Q47:S47) -> 0 | U47: =H47+L47+P47+T47 -> 0 | V47: =IF(D47=0,0,U47/D47) -> 0
B48: Lynnette (Dev) | C48: Development | D48: 5871 | H48: =SUM(E48:G48) -> 0 | L48: =SUM(I48:K48) -> 0 | P48: =SUM(M48:O48) -> 0 | T48: =SUM(Q48:S48) -> 0 | U48: =H48+L48+P48+T48 -> 0 | V48: =IF(D48=0,0,U48/D48) -> 0
B49: Lynnette (Prog) | C49: Programs | D49: 44035 | H49: =SUM(E49:G49) -> 0 | L49: =SUM(I49:K49) -> 0 | P49: =SUM(M49:O49) -> 0 | T49: =SUM(Q49:S49) -> 0 | U49: =H49+L49+P49+T49 -> 0 | V49: =IF(D49=0,0,U49/D49) -> 0
...

Sheet Executive Dashboard
A1: THE FLOURISH COLLECTIVE
A2: Financial Performance Tracker & 2030 Projection
A4: Metric | B4: FY21 | C4: FY22 | D4: FY23 | E4: FY24 | F4: FY25 Plan | G4: FY25 Actual | H4: FY25 % Plan | I4: FY26 Budget | J4: FY26 Actual | K4: FY26 % Plan | L4: FY27 Proj | M4: FY28 Proj | N4: FY29 Proj | O4: FY30 Proj
A5: Community Contributions | B5: 74317 | C5: 82970 | D5: 120435 | E5: 96823 | F5: 139000 | G5: 362109 | H5: =IF(F5=0,0,G5/F5) -> 2.6051007 | I5: ='Current Year'!D6 -> 385000 | J5: ='Progress Tracker'!U6 -> 54740 | K5: =IF(I5=0,0,J5/I5) -> 0.14218182
A6: Merchandise | B6: 963 | C6: 1443 | D6: 0 | E6: 0 | F6: 1500 | G6: 1142 | H6: =IF(F6=0,0,G6/F6) -> 0.76133333 | I6: ='Current Year'!D13 -> 2000 | J6: ='Progress Tracker'!U13 -> 0 | K6: =IF(I6=0,0,J6/I6) -> 0
A7: Annual Gathering | B7: 0 | C7: 0 | D7: 0 | E7: 0 | F7: 25000 | G7: 9323 | H7: =IF(F7=0,0,G7/F7) -> 0.37292 | I7: ='Current Year'!D14 -> 20000 | J7: ='Progress Tracker'!U14 -> 0 | K7: =IF(I7=0,0,J7/I7) -> 0
A8: Gathering Scholarships | B8: 0 | C8: 0 | D8: 0 | E8: 0 | F8: 0 | G8: 0 | H8: =IF(F8=0,0,G8/F8) -> 0 | I8: ='Current Year'!D15 -> 0 | J8: ='Progress Tracker'!U15 -> 0 | K8: =IF(I8=0,0,J8/I8) -> 0
A9: Fundraising Events | B9: 0 | C9: 0 | D9: 0 | E9: 0 | F9: 50000 | G9: 94011 | H9: =IF(F9=0,0,G9/F9) -> 1.88022 | I9: ='Current Year'!D16 -> 100000 | J9: ='Progress Tracker'!U16 -> 12899.79 | K9: =IF(I9=0,0,J9/I9) -> 0.1289979
A10: Learning Events | B10: 0 | C10: 0 | D10: 0 | E10: 0 | F10: 0 | G10: 6513 | H10: =IF(F10=0,0,G10/F10) -> 0 | I10: ='Current Year'!D17 -> 10000 | J10: ='Progress Tracker'!U17 -> 3615 | K10: =IF(I10=0,0,J10/I10) -> 0.3615
A11: Reimbursables/Misc | B11: 0 | C11: 0 | D11: 0 | E11: 0 | F11: 0 | G11: 1278 | H11: =IF(F11=0,0,G11/F11) -> 0 | I11: ='Current Year'!D20 -> 0 | J11: ='Progress Tracker'!U20 -> 0 | K11: =IF(I11=0,0,J11/I11) -> 0
A12: TOTAL REVENUE | B12: 200963 | C12: 205000 | D12: 200000 | E12: 359823 | F12: 465636 | G12: 474376 | H12: =IF(F12=0,0,G12/F12) -> 1.01877 | I12: ='Current Year'!D21 -> 517000 | J12: ='Progress Tracker'!U21 -> 71254.79 | K12: =IF(I12=0,0,J12/I12) -> 0.13782358
A14: Grantmaking | B14: 79973 | C14: 55570 | D14: 57000 | E14: 79800 | F14: 75000 | G14: 31603 | H14: =IF(F14=0,0,G14/F14) -> 0.42137333 | I14: ='Current Year'!E67 -> 50000 | J14: ='Progress Tracker'!U69 -> 0 | K14: =IF(I14=0,0,J14/I14) -> 0
A15: Development/Donor Care | B15: 21341 | C15: 31773 | D15: 19862 | E15: 33964 | F15: 57000 | G15: 177910 | H15: =IF(F15=0,0,G15/F15) -> 3.1212281 | I15: ='Current Year'!E64 -> 121661 | J15: ='Progress Tracker'!U66 -> 0 | K15: =IF(I15=0,0,J15/I15) -> 0
A16: Programs/Education | B16: 0 | C16: 0 | D16: 0 | E16: 114416 | F16: 146250 | G16: 173736 | H16: =IF(F16=0,0,G16/F16) -> 1.1879385 | I16: ='Current Year'!E65 -> 174475 | J16: ='Progress Tracker'!U67 -> 0 | K16: =IF(I16=0,0,J16/I16) -> 0
A17: Overhead | B17: 132345 | C17: 196162 | D17: 262979 | E17: 142126 | F17: 178750 | G17: 54174 | H17: =IF(F17=0,0,G17/F17) -> 0.30307133 | I17: ='Current Year'!E66 -> 167144 | J17: ='Progress Tracker'!U68 -> 0 | K17: =IF(I17=0,0,J17/I17) -> 0
A18: TOTAL EXPENSES | B18: 233659 | C18: 283505 | D18: 339841 | E18: 370306 | F18: 457000 | G18: 437423 | H18: =IF(F18=0,0,G18/F18) -> 0.95716193 | I18: ='Current Year'!D61 -> 513280 | J18: ='Progress Tracker'!U60 -> 0 | K18: =IF(I18=0,0,J18/I18) -> 0
A20: NET INCOME | B20: -32696 | C20: -78505 | D20: -139841 | E20: -10483 | F20: 8636 | G20: 36953 | H20: =H12-H18 -> 0.061608101 | I20: ='Current Year'!D69 -> 3720 | J20: ='Progress Tracker'!U62 -> 71254.79 | K20: =K12-K18 -> 0.13782358
A22: COMMUNITY GROWTH & GIVING
A23: # Active Allies | B23: 63 | C23: 136 | D23: 178 | E23: 87 | F23: 104 | G23: 272 | H23: =IFERROR((G22-F22)/F22,0) -> 0 | I23: 330 | J23: 0 | K23: =IFERROR((J22-I22)/I22,0) -> 0
A24: # Donors | B24: 145 | C24: 106 | D24: 110 | E24: 122 | F24: 134 | G24: 173 | H24: =(G23-F23)/F23 -> 1.6153846 | I24: 198 | J24: 0 | K24: =(J23-I23)/I23 -> -1
A25: Average Donation ($) | B25: 512 | C25: 783 | D25: 1094 | E25: 885 | F25: 1000 | G25: 1364 | H25: =(G24-F24)/F24 -> 0.29104478 | I25: 1279 | J25: 0 | K25: =(J24-I24)/I24 -> -1
A26: % Community Giving | B26: =IFERROR(B23/B22,0) -> 0 | C26: =IFERROR(C23/C22,0) -> 0 | D26: =IFERROR(D23/D22,0) -> 0 | E26: =IFERROR(E23/E22,0) -> 0 | F26: =IFERROR(F23/F22,0) -> 0 | G26: =IFERROR(G23/G22,0) -> 0 | H26: =(G25-F25)/F25 -> 0.364 | I26: =IFERROR(I23/I22,0) -> 0 | J26: =IFERROR(J23/J22,0) -> 0 | K26: =IFERROR((J25-I25)/I25,0) -> -1
A27: Community Growth % | B27: 0 | C27: =IFERROR((C22-B22)/B22,0) -> 0 | D27: =IFERROR((D22-C22)/C22,0) -> 0 | E27: =IFERROR((E22-D22)/D22,0) -> 0 | F27: =IFERROR((F22-E22)/E22,0) -> 0 | G27: =IFERROR((G22-E22)/E22,0) -> 0 | H27: =IFERROR((G26-F26)/F26,0) -> 0 | I27: =IFERROR((I22-G22)/G22,0) -> 0 | J27: =IFERROR((J22-G22)/G22,0) -> 0 | K27: =IFERROR((J26-I26)/I26,0) -> 0
A29: PROGRAM ENGAGEMENT
A30: Events Total | B30: 13 | C30: 28 | D30: 39 | E30: 28 | G30: 98
A31: Unique Attendees | D31: 111 | E31: 81 | G31: 190
A32: Total Attendees | B32: 304 | C32: 522 | D32: 376 | E32: 433 | G32: 923

Sheet Planning Proforma
A1: PLANNING PROFORMA & SCENARIO ANALYSIS
A2: Edit BLUE cells to adjust projections. FY26 pulls from Current Year Budget. Gray cells are calculated.
A4: PROJECTION ASSUMPTIONS
A5: Assumption | B5: FY26 (Current) | C5: FY27 | D5: FY28 | E5: FY29 | F5: FY30 | G5: Notes
A6: REVENUE GROWTH
A7: Community Contributions Growth % | B7: N/A | C7: 0.1 | D7: 0.15 | E7: 0.15 | F7: 0.15 | G7: Year-over-year growth
A8: Leadership Board Contributions ($) | B8: 0 | C8: 20000 | D8: 20000 | E8: 20000 | F8: 20000 | G8: Fixed annual amount
A9: Executive Board Contributions ($) | B9: 0 | C9: 25000 | D9: 25000 | E9: 25000 | F9: 25000 | G9: Fixed annual amount
A10: NFF Contributions ($) | B10: 0 | C10: 100000 | D10: 50000 | E10: 50000 | F10: 50000 | G10: Declining per agreement
A11: Major Donor Growth % | B11: N/A | C11: 0.5 | D11: 0.25 | E11: 0.2 | F11: 0.15 | G11: Year-over-year growth
A12: Fundraising Events Growth % | B12: N/A | C12: 0.1 | D12: 0.1 | E12: 0.1 | F12: 0.1 | G12: Year-over-year growth
A13: Learning Events Growth % | B13: N/A | C13: 0.2 | D13: 0.15 | E13: 0.15 | F13: 0.1 | G13: Year-over-year growth
A15: EXPENSE GROWTH
A16: Staff Cost Growth % | B16: N/A | C16: 0.03 | D16: 0.03 | E16: 0.03 | F16: 0.03 | G16: Annual raises/benefits
A17: Program Cost Growth % | B17: N/A | C17: 0.1 | D17: 0.1 | E17: 0.1 | F17: 0.1 | G17: Scaling programs
A18: Overhead as % of Total | B18: N/A | C18: 0.12 | D18: 0.12 | E18: 0.12 | F18: 0.12 | G18: Target overhead ratio
A19: Grantmaking Target ($) | B19: 50000 | C19: 75000 | D19: 100000 | E19: 150000 | F19: 200000 | G19: Annual grants awarded
A21: COMMUNITY GROWTH
A22: Community Size Growth % | B22: N/A | C22: 0.22 | D22: 0.23 | E22: 0.24 | F22: 0.25 | G22: Member growth rate
A23: Donor Conversion Rate | B23: 0.6 | C23: 0.6 | D23: 0.6 | E23: 0.6 | F23: 0.6 | G23: % of community who give
A24: Average Donation Growth % | B24: N/A | C24: 0.05 | D24: 0.05 | E24: 0.03 | F24: 0.03 | G24: Year-over-year growth
A26: 2030 STRATEGIC TARGETS
A27: $1M+ Grants Given (Cumulative) | B27: 310000 | C27: 385000 | D27: 485000 | E27: 635000 | F27: 835000
A28: 1,000+ Active Allies | B28: 272 | C28: 332 | D28: 408 | E28: 506 | F28: 633
A29: 50 Impact Partner Organizations | B29: 21 | C29: 28 | D29: 35 | E29: 42 | F29: 50
A30: 20,000 Individuals Engaged (Cumulative) | B30: 1800 | C30: 4000 | D30: 7000 | E30: 12000 | F30: 20000
A33: REVENUE PROJECTIONS
A34: Account | B34: FY26 Budget | C34: FY27 Proj | D34: FY28 Proj | E34: FY29 Proj | F34: FY30 Proj
A35: Community Contributions | B35: =SUM(B36:B40) -> 385000 | C35: =SUM(C36:C40) -> 355500 | D35: =SUM(D36:D40) -> 352075 | E35: =SUM(E36:E40) -> 400011.25 | F35: =SUM(F36:F40) -> 445762.94
A36: Leadership Board Contributions | B36: ='Current Year'!E8 -> 20000 | C36: =C$8 -> 20000 | D36: =D$8 -> 20000 | E36: =E$8 -> 20000 | F36: =F$8 -> 20000
A37: Executive Board Contributions | B37: ='Current Year'!E9 -> 60000 | C37: =C$9 -> 25000 | D37: =D$9 -> 25000 | E37: =E$9 -> 25000 | F37: =F$9 -> 25000
A38: NFF Contributions | B38: ='Current Year'!E10 -> 150000 | C38: =C$10 -> 100000 | D38: =D$10 -> 50000 | E38: =E$10 -> 50000 | F38: =F$10 -> 50000
A39: Major Donor Contributions | B39: ='Current Year'!E11 -> 100000 | C39: =B39*(1+C$11) -> 150000 | D39: =C39*(1+D$11) -> 187500 | E39: =D39*(1+E$11) -> 225000 | F39: =E39*(1+F$11) -> 258750
A40: All Other Community | B40: ='Current Year'!E12 -> 55000 | C40: =B40*(1+C$7) -> 60500 | D40: =C40*(1+D$7) -> 69575 | E40: =D40*(1+E$7) -> 80011.25 | F40: =E40*(1+F$7) -> 92012.938
A41: Merchandise | B41: ='Current Year'!D13 -> 2000 | C41: =B41 -> 2000 | D41: =C41 -> 2000 | E41: =D41 -> 2000 | F41: =E41 -> 2000
A42: Annual Gathering | B42: ='Current Year'!D14 -> 20000 | C42: =B42*1.05 -> 21000 | D42: =C42*1.05 -> 22050 | E42: =D42*1.05 -> 23152.5 | F42: =E42*1.05 -> 24310.125
A43: Gathering Scholarships | B43: ='Current Year'!D15 -> 0 | C43: =B43 -> 0 | D43: =C43 -> 0 | E43: =D43 -> 0 | F43: =E43 -> 0
A44: Fundraising Events | B44: ='Current Year'!D16 -> 100000 | C44: =B44*(1+C$12) -> 110000 | D44: =C44*(1+D$12) -> 121000 | E44: =D44*(1+E$12) -> 133100 | F44: =E44*(1+F$12) -> 146410
A45: Learning Events | B45: =SUM(B46:B47) -> 10000 | C45: =SUM(C46:C47) -> 12000 | D45: =SUM(D46:D47) -> 13800 | E45: =SUM(E46:E47) -> 15870 | F45: =SUM(F46:F47) -> 17457
A46: Online Learning Events | B46: ='Current Year'!E18 -> 5000 | C46: =B46*(1+C$13) -> 6000 | D46: =C46*(1+D$13) -> 6900 | E46: =D46*(1+E$13) -> 7935 | F46: =E46*(1+F$13) -> 8728.5
...

Sheet People Costs
A1: 2025 Proforma Staffing Plan A | G1: Mid Year Changes | I1: Total Cost | J1: Role | K1: Notes
A2: Role | B2: Type | C2: Rate/hr | D2: Hrs/wk | E2: Total Cost | F2: Notes | I2: 150000 | J2: Exec Director
A3: Exec Director | B3: FTE | C3: NA | D3: 40 | E3: 150000 | F3: Michelle full time | G3: 150000 | I3: 60000 | J3: Community Engagement | K3: Recommend no change to salary, only to job description.
A4: Community Engagement | B4: PTE | C4: 35 | D4: 25 | E4: 72000 | F4: Lynette - no change | G4: 90000 | I4: 30000 | J4: Learning & Ally Development
A5: Learning & Ally Develoment | B5: 1099 one time | C5: 35 | D5: 20 | E5: 30000 | F5: Kristin maxed | G5: 25000 | I5: 50000 | J5: Comms & Marketing | K5: Agree increase to full time and update Title & JD to include all roles
A6: Comms & Marketing | B6: 1099 one time | C6: 35 | D6: 30 | E6: 35000 | F6: Lauren PT Time | G6: 50000 | I6: 20000 | J6: Administrative & Content Support | K6: Agree to hire, recommend 20 hrs/wk instead of 10
A7: Administrative & Content Support | B7: 1099 one time | C7: 25 | D7: 10 | E7: 10000 | F7: Contractor to hire | G7: 10000 | I7: 0 | J7: Grant Writing | K7: Recommend do not spend this
A8: Grant Writing | B8: 1099 ongoing | C8: - | D8: - | E8: 20000 | F8: Contractor expert | G8: 0 | I8: 0 | J8: Data Analytics Design & Development | K8: Recommend design and requirements definition Q2/Q3 FY25, add development to FY26 budget.
A9: Data Analytics Design & Development | B9: 1099 one time | C9: - | D9: - | E9: 10000 | F9: Contractor expert | G9: 0 | I9: =SUM(I2:I8) -> 310000
A10: TOTAL People Cost | E10: =SUM(E3:E9) -> 327000 | G10: =SUM(G2:G9) -> 325000
A12: 2025 Proforma Staffing Plan B
A13: Role | B13: Type | C13: Rate/hr | D13: Hrs/wk | E13: Total Cost | F13: Notes
A14: Exec Director | B14: FTE | C14: NA | D14: 32 | E14: =E3-9000 -> 141000 | F14: Michele 32 hrs/wk, reduce 401k match by $9k
A15: Community Engagement | B15: FTE | C15: 35 | E15: 45000 | F15: Lynette moved to 60% time
A16: Learning & Ally Develoment | B16: 1099 one time | C16: 35 | D16: 20 | E16: =E5 -> 30000 | F16: Kristin maxed PT
A17: Comms & Marketing | B17: 1099 one time | C17: 20 | D17: 30 | E17: =E6 -> 35000 | F17: Lauren Filomeo PT
A18: Administrative & Content Support | B18: 1099 one time | C18: 25 | D18: 15 | E18: 13500 | F18: Contractor expert
A19: Grant Writing | B19: 1099 ongoing | C19: - | D19: - | E19: =E8 -> 20000 | F19: Contractor expert
A20: Data Analytics Design & Development | B20: 1099 one time | C20: - | D20: - | E20: =E9 -> 10000 | F20: Contractor expert
A21: TOTAL People Cost | E21: =SUM(E14:E20) -> 294500
A24: Projection 2025 Q2-4
A25: Employee | B25: Gross earnings $35 per hour | C25: Total employee deductions | D25: Total employer contributions | E25: Total employee taxes | F25: Total employer taxes | G25: Net pay
A27: Lynnette Marshall | B27: 42000 | F27: 3000
A30: Percentage of time spent | B30: Education/Allyship programs | C30: Operations | D30: Development | F30: FY24 - $114, 416
A31: Director | B31: 0.3 | C31: 0.4 | D31: 0.3 | F31: FY 25 Projections --
A32: Learning Consultant | B32: 1 | F32: FY21
A33: Community Engagement | B33: 0.75 | C33: 0.15 | D33: 0.1 | F33: FY22
A34: Communications | B34: 0.5 | C34: 0.5 | F34: FY 23 -
A36: Michele's Notes
A37: 2024
A38: Employee | B38: Gross earnings | C38: Total employee deductions | D38: Total employer contributions | E38: Total employee taxes | F38: Total employer taxes | G38: Net pay
A39: Lynnette Marshall - avg $33 hourly | B39: 63420.8 | C39: 1268.45 | D39: 4439.48 | E39: 11168.97 | F39: 4851.69 | G39: 50983.38
A40: Michele Sbrana | B40: 118364.78 | C40: 2466.16 | D40: 18619.35 | E40: 36822.37 | F40: 9292.91 | G40: 79076.25
A41: .025% increase for 2025 | B41: 2950
B42: =SUM(B40:B41) -> 121314.78 | F42: 9400
A43: Totals | B43: Gross earnings Total | C43: Total employee deductions Total | D43: Total employer contributions Total | E43: Total employee taxes Total | F43: Total employer taxes Total | G43: Net pay Total
B44: 181785.58 | C44: 3734.61 | D44: 23058.83 | E44: 47991.34 | F44: 14144.6 | G44: 130059.63
A46: 2024 | B46: 2024 | C46: hours | D46: 2025 | E46: hours Jan + Feb
A47: Contractors
A48: Learning/K Malvadkar | B48: 23314 | C48: 706.5 | D48: 8976.3 | E48: 255
...
